2020-06-07 10:00:08,042 ERROR: Exception on /reset_password_request [POST] [in E:\flutter\content\backend\env\lib\site-packages\flask\app.py:1892] 
Traceback (most recent call last):
  File "E:\flutter\content\backend\env\lib\site-packages\flask\app.py", line 2447, in wsgi_app
    response = self.full_dispatch_request()
  File "E:\flutter\content\backend\env\lib\site-packages\flask\app.py", line 1952, in full_dispatch_request
    rv = self.handle_user_exception(e)
  File "E:\flutter\content\backend\env\lib\site-packages\flask\app.py", line 1821, in handle_user_exception
    reraise(exc_type, exc_value, tb)
  File "E:\flutter\content\backend\env\lib\site-packages\flask\_compat.py", line 39, in reraise
    raise value
  File "E:\flutter\content\backend\env\lib\site-packages\flask\app.py", line 1950, in full_dispatch_request
    rv = self.dispatch_request()
  File "E:\flutter\content\backend\env\lib\site-packages\flask\app.py", line 1936, in dispatch_request
    return self.view_functions[rule.endpoint](**req.view_args)
  File "E:\flutter\content\backend\app\routes.py", line 301, in reset_password_request
    send_password_reset_email(user)
  File "E:\flutter\content\backend\app\email.py", line 14, in send_password_reset_email
    token = user.get_reset_password_token()
  File "E:\flutter\content\backend\app\models.py", line 109, in get_reset_password_token
    app.config['SECRET_KEY'], algorithm=['HS256']
  File "E:\flutter\content\backend\env\lib\site-packages\jwt\api_jwt.py", line 61, in encode
    cls=json_encoder
  File "c:\users\snehm\appdata\local\programs\python\python37\Lib\json\__init__.py", line 238, in dumps
    **kw).encode(obj)
  File "c:\users\snehm\appdata\local\programs\python\python37\Lib\json\encoder.py", line 199, in encode
    chunks = self.iterencode(o, _one_shot=True)
  File "c:\users\snehm\appdata\local\programs\python\python37\Lib\json\encoder.py", line 257, in iterencode
    return _iterencode(o, 0)
  File "c:\users\snehm\appdata\local\programs\python\python37\Lib\json\encoder.py", line 179, in default
    raise TypeError(f'Object of type {o.__class__.__name__} '
TypeError: Object of type ObjectId is not JSON serializable
2020-06-07 10:03:10,529 ERROR: Exception on /reset_password_request [POST] [in E:\flutter\content\backend\env\lib\site-packages\flask\app.py:1892] 
Traceback (most recent call last):
  File "E:\flutter\content\backend\env\lib\site-packages\flask\app.py", line 2447, in wsgi_app
    response = self.full_dispatch_request()
  File "E:\flutter\content\backend\env\lib\site-packages\flask\app.py", line 1952, in full_dispatch_request
    rv = self.handle_user_exception(e)
  File "E:\flutter\content\backend\env\lib\site-packages\flask\app.py", line 1821, in handle_user_exception
    reraise(exc_type, exc_value, tb)
  File "E:\flutter\content\backend\env\lib\site-packages\flask\_compat.py", line 39, in reraise
    raise value
  File "E:\flutter\content\backend\env\lib\site-packages\flask\app.py", line 1950, in full_dispatch_request
    rv = self.dispatch_request()
  File "E:\flutter\content\backend\env\lib\site-packages\flask\app.py", line 1936, in dispatch_request
    return self.view_functions[rule.endpoint](**req.view_args)
  File "E:\flutter\content\backend\app\routes.py", line 301, in reset_password_request
    send_password_reset_email(user)
  File "E:\flutter\content\backend\app\email.py", line 14, in send_password_reset_email
    token = user.get_reset_password_token()
  File "E:\flutter\content\backend\app\models.py", line 109, in get_reset_password_token
    app.config['SECRET_KEY'], algorithm=['HS256']
  File "E:\flutter\content\backend\env\lib\site-packages\jwt\api_jwt.py", line 65, in encode
    json_payload, key, algorithm, headers, json_encoder
  File "E:\flutter\content\backend\env\lib\site-packages\jwt\api_jws.py", line 88, in encode
    if algorithm not in self._valid_algs:
TypeError: unhashable type: 'list'
2020-06-07 10:10:17,830 ERROR: Exception on /reset_password_request [POST] [in E:\flutter\content\backend\env\lib\site-packages\flask\app.py:1892] 
Traceback (most recent call last):
  File "E:\flutter\content\backend\env\lib\site-packages\flask\app.py", line 2447, in wsgi_app
    response = self.full_dispatch_request()
  File "E:\flutter\content\backend\env\lib\site-packages\flask\app.py", line 1952, in full_dispatch_request
    rv = self.handle_user_exception(e)
  File "E:\flutter\content\backend\env\lib\site-packages\flask\app.py", line 1821, in handle_user_exception
    reraise(exc_type, exc_value, tb)
  File "E:\flutter\content\backend\env\lib\site-packages\flask\_compat.py", line 39, in reraise
    raise value
  File "E:\flutter\content\backend\env\lib\site-packages\flask\app.py", line 1950, in full_dispatch_request
    rv = self.dispatch_request()
  File "E:\flutter\content\backend\env\lib\site-packages\flask\app.py", line 1936, in dispatch_request
    return self.view_functions[rule.endpoint](**req.view_args)
  File "E:\flutter\content\backend\app\routes.py", line 301, in reset_password_request
    send_password_reset_email(user)
  File "E:\flutter\content\backend\app\email.py", line 18, in send_password_reset_email
    sender=app.config['ADMINS'][0],
NameError: name 'app' is not defined
2020-06-07 10:12:21,779 ERROR: Exception on /reset_password_request [POST] [in E:\flutter\content\backend\env\lib\site-packages\flask\app.py:1892] 
Traceback (most recent call last):
  File "E:\flutter\content\backend\env\lib\site-packages\flask_mail.py", line 492, in send
    message.send(connection)
  File "E:\flutter\content\backend\env\lib\site-packages\flask_mail.py", line 427, in send
    connection.send(self)
  File "E:\flutter\content\backend\env\lib\site-packages\flask_mail.py", line 192, in send
    message.rcpt_options)
  File "c:\users\snehm\appdata\local\programs\python\python37\Lib\smtplib.py", line 852, in sendmail
    self.ehlo_or_helo_if_needed()
  File "c:\users\snehm\appdata\local\programs\python\python37\Lib\smtplib.py", line 600, in ehlo_or_helo_if_needed
    if not (200 <= self.ehlo()[0] <= 299):
  File "c:\users\snehm\appdata\local\programs\python\python37\Lib\smtplib.py", line 440, in ehlo
    self.putcmd(self.ehlo_msg, name or self.local_hostname)
  File "c:\users\snehm\appdata\local\programs\python\python37\Lib\smtplib.py", line 367, in putcmd
    self.send(str)
  File "c:\users\snehm\appdata\local\programs\python\python37\Lib\smtplib.py", line 359, in send
    raise SMTPServerDisconnected('please run connect() first')
smtplib.SMTPServerDisconnected: please run connect() first

During handling of the above exception, another exception occurred:

Traceback (most recent call last):
  File "E:\flutter\content\backend\env\lib\site-packages\flask\app.py", line 2447, in wsgi_app
    response = self.full_dispatch_request()
  File "E:\flutter\content\backend\env\lib\site-packages\flask\app.py", line 1952, in full_dispatch_request
    rv = self.handle_user_exception(e)
  File "E:\flutter\content\backend\env\lib\site-packages\flask\app.py", line 1821, in handle_user_exception
    reraise(exc_type, exc_value, tb)
  File "E:\flutter\content\backend\env\lib\site-packages\flask\_compat.py", line 39, in reraise
    raise value
  File "E:\flutter\content\backend\env\lib\site-packages\flask\app.py", line 1950, in full_dispatch_request
    rv = self.dispatch_request()
  File "E:\flutter\content\backend\env\lib\site-packages\flask\app.py", line 1936, in dispatch_request
    return self.view_functions[rule.endpoint](**req.view_args)
  File "E:\flutter\content\backend\app\routes.py", line 301, in reset_password_request
    send_password_reset_email(user)
  File "E:\flutter\content\backend\app\email.py", line 22, in send_password_reset_email
    html_body=render_template('email/reset_password.html', user=user, token=token)
  File "E:\flutter\content\backend\app\email.py", line 11, in send_email
    mail.send(msg)
  File "E:\flutter\content\backend\env\lib\site-packages\flask_mail.py", line 492, in send
    message.send(connection)
  File "E:\flutter\content\backend\env\lib\site-packages\flask_mail.py", line 152, in __exit__
    self.host.quit()
  File "c:\users\snehm\appdata\local\programs\python\python37\Lib\smtplib.py", line 984, in quit
    res = self.docmd("quit")
  File "c:\users\snehm\appdata\local\programs\python\python37\Lib\smtplib.py", line 420, in docmd
    self.putcmd(cmd, args)
  File "c:\users\snehm\appdata\local\programs\python\python37\Lib\smtplib.py", line 367, in putcmd
    self.send(str)
  File "c:\users\snehm\appdata\local\programs\python\python37\Lib\smtplib.py", line 359, in send
    raise SMTPServerDisconnected('please run connect() first')
smtplib.SMTPServerDisconnected: please run connect() first
